Workbook

Sheet Лист ответов
B2: № | C2: ЗАДАНИЕ | D2: ОТВЕТ | F2: СТАТУС
A3: 1 | B3: 1 | C3: Вычислите общую сумму начислений для всех абонентов в тенге | D3: =SUM('[1]База данных'!D2:D624) -> 3899.58 | F3: =IF(ISERROR(IF(ROUND(D3,2)=ROUND(O3,2),"Правильный ответ","Неправильный ответ")),"Неправильный ответ",IF(ROUND(D3,2)=ROUND(O3,2),"Правильный ответ","Неправильный ответ")) -> Правильный ответ | O3: 3899.58
A4: 2 | B4: =IF(C4="","",A4) -> 2 | C4: =IF(F3="Правильный ответ","Вычислите общую продолжительность разговоров для всех абонентов в секундах","") -> Вычислите общую продолжительность разговоров для всех абонентов в секундах | D4: =SUM('[1]База данных'!E2:E624) -> 7883 | F4: =IF(ISERROR(IF(D4=D4,"Правильный ответ","Неправильный ответ")),"Неправильный ответ",IF(D4=O4,"Правильный ответ","Неправильный ответ")) -> Правильный ответ | O4: 7883
A5: 3 | B5: =IF(C5="","",A5) -> 3 | C5: =IF(F4="Правильный ответ","Вычислите общее количество звонков всех абонентов (одна строка = один звонок)","") -> Вычислите общее количество звонков всех абонентов (одна строка = один звонок) | D5: =COUNT('[1]База данных'!A2:A624) -> 623 | F5: =IF(ISERROR(IF(D5=D5,"Правильный ответ","Неправильный ответ")),"Неправильный ответ",IF(D5=O5,"Правильный ответ","Неправильный ответ")) -> Правильный ответ | O5: 623
A6: 4 | B6: =IF(C6="","",A6) -> 4 | C6: =IF(F5="Правильный ответ","Вычислите общую продолжительность разговоров для всех абонентов в минутах, округлив значение до десятичного знака (математическое округление)","") -> Вычислите общую продолжительность разговоров для всех абонентов в минутах, округлив значение до десятичного знака (математическое округление) | D6: =ROUND(SUM('[1]База данных'!E2:E624)/60,1) -> 131.4 | F6: =IF(ISERROR(IF(D6=D6,"Правильный ответ","Неправильный ответ")),"Неправильный ответ",IF(D6=O6,"Правильный ответ","Неправильный ответ")) -> Правильный ответ | O6: 131.4
A7: 5 | B7: =IF(C7="","",A7) -> 5 | C7: =IF(F6="Правильный ответ","Вычислите сумму начислений для звонков внутри сети","") -> Вычислите сумму начислений для звонков внутри сети | D7: =SUMIF('[1]База данных'!C2:C624,'[1]База данных'!$C$2,'[1]База данных'!D2:D624) -> 3172.39 | F7: =IF(ISERROR(IF(ROUND(D7,2)=ROUND(O7,2),"Правильный ответ","Неправильный ответ")),"Неправильный ответ",IF(ROUND(D7,2)=ROUND(O7,2),"Правильный ответ","Неправильный ответ")) -> Правильный ответ | O7: 3172.39
A8: 6 | B8: =IF(C8="","",A8) -> 6 | C8: =IF(F7="Правильный ответ","Вычислите продолжительность разговоров на других операторов в секундах","") -> Вычислите продолжительность разговоров на других операторов в секундах | D8: =SUMIF('[1]База данных'!C2:C624,'[1]База данных'!$C$589,'[1]База данных'!E2:E624) -> 362 | F8: =IF(ISERROR(IF(D8=D8,"Правильный ответ","Неправильный ответ")),"Неправильный ответ",IF(D8=O8,"Правильный ответ","Неправильный ответ")) -> Правильный ответ | O8: 362
A9: 7 | B9: =IF(C9="","",A9) -> 7 | C9: =IF(F8="Правильный ответ","Вычислите общее количество звонков на тарифном плане 2 (одна строка = один звонок)","") -> Вычислите общее количество звонков на тарифном плане 2 (одна строка = один звонок) | D9: =COUNTIF('[1]База данных'!B2:B624,'[1]База данных'!B254) -> 66 | F9: =IF(ISERROR(IF(D9=D9,"Правильный ответ","Неправильный ответ")),"Неправильный ответ",IF(D9=O9,"Правильный ответ","Неправильный ответ")) -> Правильный ответ | O9: 66
A10: 8 | B10: =IF(C10="","",A10) -> 8 | C10: =IF(F9="Правильный ответ","Вычислите среднюю стоимость одной минуты разговора всех абонентов по всем направлениям и округлите ее до сотых (математическое округление)","") -> Вычислите среднюю стоимость одной минуты разговора всех абонентов по всем направлениям и округлите ее до сотых (математическое округление) | D10: =ROUND(D3/D6,2) -> 29.68 | F10: =IF(ISERROR(IF(D10=D10,"Правильный ответ","Неправильный ответ")),"Неправильный ответ",IF(D10=O10,"Правильный ответ","Неправильный ответ")) -> Правильный ответ | O10: 29.68
A11: 9 | B11: =IF(C11="","",A11) -> 9 | C11: =IF(F10="Правильный ответ","Вычислите среднюю продолжительность одного звонка всех абонентов по всем направлениям в секундах и округлите ее до целого числа (математическое округление)","") -> Вычислите среднюю продолжительность одного звонка всех абонентов по всем направлениям в секундах и округлите ее до целого числа (математическое округление) | D11: =ROUND(AVERAGE('[1]База данных'!E2:E624),0) -> 13 | F11: =IF(ISERROR(IF(D11=D11,"Правильный ответ","Неправильный ответ")),"Неправильный ответ",IF(D11=O11,"Правильный ответ","Неправильный ответ")) -> Правильный ответ | O11: 13
A12: 10 | B12: =IF(C12="","",A12) -> 10 | C12: =IF(F11="Правильный ответ","Вычислите сумму продолжительности разговоров в секундах на городской для тарифного плана 5","") -> Вычислите сумму продолжительности разговоров в секундах на городской для тарифного плана 5 | D12: =SUMIFS('[1]База данных'!E2:E624,'[1]База данных'!C2:C624,'[1]База данных'!$C$505,'[1]База данных'!B2:B624,'[1]База данных'!$B$510) -> 33 | F12: =IF(ISERROR(IF(D12=D12,"Правильный ответ","Неправильный ответ")),"Неправильный ответ",IF(D12=O12,"Правильный ответ","Неправильный ответ")) -> Правильный ответ | O12: 33
A13: 11 | B13: =IF(C13="","",A13) -> 11 | C13: =IF(F12="Правильный ответ","Вычислите количество звонков на межнар для тарифного плана 1","") -> Вычислите количество звонков на межнар для тарифного плана 1 | D13: =COUNTIFS('[1]База данных'!C2:C624,'[1]База данных'!$C$139,'[1]База данных'!B2:B624,'[1]База данных'!B2) -> 6 | F13: =IF(ISERROR(IF(D13=D13,"Правильный ответ","Неправильный ответ")),"Неправильный ответ",IF(D13=O13,"Правильный ответ","Неправильный ответ")) -> Правильный ответ | O13: 6
A14: 12 | B14: =IF(C14="","",A14) -> 12 | C14: =IF(F13="Правильный ответ","Вычислите долю продолжительности внутрисетевых звонков от всех звонков. Округлите до сотых в процентах","") -> Вычислите долю продолжительности внутрисетевых звонков от всех звонков. Округлите до сотых в процентах | D14: =ROUND(SUMIF('[1]База данных'!C2:C624,'[1]База данных'!$C$586,'[1]База данных'!E2:E624) / SUM('[1]База данных'!E2:E624),4) -> 0.9155 | F14: =IF(ISERROR(IF(D14=D14,"Правильный ответ","Неправильный ответ")),"Неправильный ответ",IF(D14=O14,"Правильный ответ","Неправильный ответ")) -> Правильный ответ | O14: 0.9155
A15: 13 | B15: =IF(C15="","",A15) -> 13 | C15: =IF(F14="Правильный ответ","Вычислите долю начислений тарифного плана 1 от общих начислений по всем тарифам. Округлите до сотых в процентах","") -> Вычислите долю начислений тарифного плана 1 от общих начислений по всем тарифам. Округлите до сотых в процентах | D15: =ROUND(SUMIF('[1]База данных'!B2:B624,'[1]База данных'!$B$2,'[1]База данных'!D2:D624)/SUM('[1]База данных'!D2:D624),4) -> 0.3642 | F15: =IF(ISERROR(IF(D15=D15,"Правильный ответ","Неправильный ответ")),"Неправильный ответ",IF(D15=O15,"Правильный ответ","Неправильный ответ")) -> Правильный ответ | O15: 0.3642
A16: 14 | B16: =IF(C16="","",A16) -> 14 | C16: =IF(F15="Правильный ответ","Вычислите общее количество уникальных абонентов","") -> Вычислите общее количество уникальных абонентов | D16: =COUNT('База данных'!G2:G293) -> 292 | F16: =IF(ISERROR(IF(D16=D16,"Правильный ответ","Неправильный ответ")),"Неправильный ответ",IF(D16=O16,"Правильный ответ","Неправильный ответ")) -> Правильный ответ | O16: 292
A17: 15 | B17: =IF(C17="","",A17) -> 15 | C17: =IF(F16="Правильный ответ","Укажите общее количество уникальных пользователей внутрисетевых звонков","") -> Укажите общее количество уникальных пользователей внутрисетевых звонков | D17: =COUNTIF('База данных'!M2:M340,'База данных'!$M$305) -> 290 | F17: =IF(ISERROR(IF(D17=D17,"Правильный ответ","Неправильный ответ")),"Неправильный ответ",IF(D17=O17,"Правильный ответ","Неправильный ответ")) -> Правильный ответ | O17: 290
A18: 16 | B18: =IF(C18="","",A18) -> 16 | C18: =IF(F17="Правильный ответ","Укажите общее количество уникальных абонентов на тарифном плане 6","") -> Укажите общее количество уникальных абонентов на тарифном плане 6 | D18: =COUNT('База данных'!P2:P64) -> 63 | F18: =IF(ISERROR(IF(D18=D18,"Правильный ответ","Неправильный ответ")),"Неправильный ответ",IF(D18=O18,"Правильный ответ","Неправильный ответ")) -> Правильный ответ | O18: 63
A19: 17 | B19: =IF(C19="","",A19) -> 17 | C19: =IF(F18="Правильный ответ","Вычислите долю уникальных абонентов тарифного плана 2 от общего количества уникальных абонентов по всем тарифам. Округлите до сотых","") -> Вычислите долю уникальных абонентов тарифного плана 2 от общего количества уникальных абонентов по всем тарифам. Округлите до сотых | D19: =ROUND(SUM('База данных'!R2:R33)/SUM('База данных'!G2:G293),4) -> 0.1096 | F19: =IF(ISERROR(IF(D19=D19,"Правильный ответ","Неправильный ответ")),"Неправильный ответ",IF(D19=O19,"Правильный ответ","Неправильный ответ")) -> Правильный ответ | O19: 0.1096
A20: 18 | B20: =IF(C20="","",A20) -> 18 | C20: =IF(F19="Правильный ответ","Рассчитайте средние начисления в тенге на одного уникального абонента, округлите значение до сотых","") -> Рассчитайте средние начисления в тенге на одного уникального абонента, округлите значение до сотых | D20: =ROUND(SUM('База данных'!D2:D624)/SUMPRODUCT(1/COUNTIF('База данных'!A2:A624,'База данных'!A2:A624)),2) -> 13.35 | F20: =IF(ISERROR(IF(D20=D20,"Правильный ответ","Неправильный ответ")),"Неправильный ответ",IF(D20=O20,"Правильный ответ","Неправильный ответ")) -> Правильный ответ | O20: 13.35
A21: 19 | B21: =IF(C21="","",A21) -> 19 | C21: =IF(F20="Правильный ответ","Рассчитайте среднюю продолжительность разговоров одного уникального абонента в минутах, округлите значение до десятых","") -> Рассчитайте среднюю продолжительность разговоров одного уникального абонента в минутах, округлите значение до десятых | D21: =ROUND(SUM('База данных'!E2:E624)/60/SUMPRODUCT(1/COUNTIF('База данных'!A2:A624,'База данных'!A2:A624)),1) -> 0.4 | F21: =IF(ISERROR(IF(D21=D21,"Правильный ответ","Неправильный ответ")),"Неправильный ответ",IF(D21=O21,"Правильный ответ","Неправильный ответ")) -> Правильный ответ | O21: 0.4
A22: 20 | B22: =IF(C22="","",A22) -> 20 | C22: =IF(F21="Правильный ответ","Укажите продолжительность разговоров на тарифном плане, на котором сидит абонент 77010000055","") -> Укажите продолжительность разговоров на тарифном плане, на котором сидит абонент 77010000055 | F22: =IF(ISERROR(IF(D22=D22,"Правильный ответ","Неправильный ответ")),"Неправильный ответ",IF(D22=O22,"Правильный ответ","Неправильный ответ")) -> Неправильный ответ | O22: 2705
A23: 21 | B23: =IF(C23="","",A23) | C23: =IF(F22="Правильный ответ","Укажите абонента, у которого наибольшее начисление","") | F23: =IF(ISERROR(IF(D23=D23,"Правильный ответ","Неправильный ответ")),"Неправильный ответ",IF(D23=O23,"Правильный ответ","Неправильный ответ")) -> Неправильный ответ | O23: 77010000109
A24: 22 | B24: =IF(C24="","",A24) | C24: =IF(F23="Правильный ответ","Укажите абонента, у которого наибольшая продолжительность разговоров на тарифном плане 5","") | F24: =IF(ISERROR(IF(D24=D24,"Правильный ответ","Неправильный ответ")),"Неправильный ответ",IF(D24=O24,"Правильный ответ","Неправильный ответ")) -> Неправильный ответ | O24: 77010000211
A25: 23 | B25: =IF(C25="","",A25) | C25: =IF(F24="Правильный ответ","Укажите абонента, который на 7 месте по общей сумме начислений","") | F25: =IF(ISERROR(IF(D25=D25,"Правильный ответ","Неправильный ответ")),"Неправильный ответ",IF(D25=O25,"Правильный ответ","Неправильный ответ")) -> Неправильный ответ | O25: 77010000133
A26: 24 | B26: =IF(C26="","",A26) | C26: =IF(F25="Правильный ответ","Какое направление не используется абонентами тарифного плана 6 (ответов может быть несколько, вписывать через запятую)","") | D26: {=_xlfn.TEXTJOIN("; ",TRUE,_xlfn._xlws.FILTER(_xlfn.UNIQUE('База данных'!C:C),ISNA(MATCH(_xlfn.UNIQUE('База данных'!C:C),_xlfn.UNIQUE(_xlfn._xlws.FILTER('База данных'!C:C,'База данных'!B:B="6")),0))))} -> #NAME? | F26: =IF(ISERROR(IF(OR(UPPER(TRIM(LEFT(D26,SEARCH(",",D26,1)-1)))&","&UPPER(TRIM(RIGHT(D26,LEN(D26)-SEARCH(",",D26,1))))=O26&","&P26,UPPER(TRIM(LEFT(D26,SEARCH(",",D26,1)-1)))&","&UPPER(TRIM(RIGHT(D26,LEN(D26)-SEARCH(",",D26,1))))=P26&","&O26),"Правильный ответ","Неправильный ответ")),"Неправильный ответ",IF(OR(UPPER(TRIM(LEFT(D26,SEARCH(",",D26,1)-1)))&","&UPPER(TRIM(RIGHT(D26,LEN(D26)-SEARCH(",",D26,1))))=O26&","&P26,UPPER(TRIM(LEFT(D26,SEARCH(",",D26,1)-1)))&","&UPPER(TRIM(RIGHT(D26,LEN(D26)-SEARCH(",",D26,1))))=P26&","&O26),"Правильный ответ","Неправильный ответ")) -> Неправильный ответ | O26: НА ГОРОДСКОЙ | P26: ДРУГОЕ
C27: =IF(F26="Правильный ответ","Тест пройден. Поздравляем!","") | D27: =SUMIF('База данных'!B:B, VLOOKUP(77010000055, 'База данных'!A:B, 2, 0), 'База данных'!E:E) -> 2705

Sheet База данных
A1: Абонент | B1: Тарифный план | C1: Направление звонка | D1: Начисления, тенге | E1: Продолжительность разговора, секунды | G1: 14 | L1: 15 | P1: 16 | R1: 17
A2: 77010000068 | B2: 1 | C2: Внутри сети | D2: 0 | E2: 0 | G2: 77010000068 | H2: Внутри сети | I2: =SUMIF(A2:A624,A2,D2:D624) -> 9.37 | L2: 77010000068 | M2: Внутри сети | N2: Внутри сети | P2: 77010000262 | R2: 77010000112
A3: 77010000001 | B3: 1 | C3: Внутри сети | D3: 0.43 | E3: 1 | G3: 77010000001 | H3: Внутри сети | I3: =SUMIF(A3:A625,A3,D3:D625) -> 16.15 | L3: 77010000001 | M3: Внутри сети | N3: Внутри сети | P3: 77010000240 | R3: 77010000114
A4: 77010000003 | B4: 1 | C4: Внутри сети | D4: 0.43 | E4: 1 | G4: 77010000003 | H4: Внутри сети | I4: =SUMIF(A4:A626,A4,D4:D626) -> 23.16 | L4: 77010000003 | M4: Внутри сети | N4: Внутри сети | P4: 77010000244 | R4: 77010000118
A5: 77010000004 | B5: 1 | C5: Внутри сети | D5: 0.43 | E5: 1 | G5: 77010000004 | H5: Внутри сети | I5: =SUMIF(A5:A627,A5,D5:D627) -> 8.95 | L5: 77010000004 | M5: Внутри сети | N5: Внутри сети | P5: 77010000245 | R5: 77010000120
A6: 77010000008 | B6: 1 | C6: Внутри сети | D6: 0.43 | E6: 1 | G6: 77010000008 | H6: Внутри сети | I6: =SUMIF(A6:A628,A6,D6:D628) -> 15.73 | L6: 77010000008 | M6: Внутри сети | N6: Внутри сети | P6: 77010000247 | R6: 77010000115
A7: 77010000052 | B7: 1 | C7: Внутри сети | D7: 0.43 | E7: 1 | G7: 77010000052 | H7: Внутри сети | I7: =SUMIF(A7:A629,A7,D7:D629) -> 11.93 | L7: 77010000052 | M7: Внутри сети | N7: Внутри сети | P7: 77010000252 | R7: 77010000121
A8: 77010000060 | B8: 1 | C8: Внутри сети | D8: 0.43 | E8: 1 | G8: 77010000060 | H8: Внутри сети | I8: =SUMIF(A8:A630,A8,D8:D630) -> 19.61 | L8: 77010000060 | M8: Внутри сети | N8: Внутри сети | P8: 77010000269 | R8: 77010000125
A9: 77010000046 | B9: 1 | C9: Внутри сети | D9: 0.43 | E9: 1 | G9: 77010000046 | H9: Внутри сети | I9: =SUMIF(A9:A631,A9,D9:D631) -> 7.25 | L9: 77010000046 | M9: Внутри сети | N9: Внутри сети | P9: 77010000273 | R9: 77010000103
A10: 77010000054 | B10: 1 | C10: Внутри сети | D10: 0.43 | E10: 1 | G10: 77010000054 | H10: Внутри сети | I10: =SUMIF(A10:A632,A10,D10:D632) -> 23.39 | L10: 77010000054 | M10: Внутри сети | N10: Внутри сети | P10: 77010000287 | R10: 77010000110
A11: 77010000062 | B11: 1 | C11: Внутри сети | D11: 0.43 | E11: 1 | G11: 77010000062 | H11: Внутри сети | I11: =SUMIF(A11:A633,A11,D11:D633) -> 15.96 | L11: 77010000062 | M11: Внутри сети | N11: Внутри сети | P11: 77010000288 | R11: 77010000128
A12: 77010000065 | B12: 1 | C12: Внутри сети | D12: 0.43 | E12: 1 | G12: 77010000065 | H12: Внутри сети | I12: =SUMIF(A12:A634,A12,D12:D634) -> 1.28 | L12: 77010000065 | M12: Внутри сети | N12: Внутри сети | P12: 77010000291 | R12: 77010000126
A13: 77010000066 | B13: 1 | C13: Внутри сети | D13: 0.43 | E13: 1 | G13: 77010000066 | H13: Внутри сети | I13: =SUMIF(A13:A635,A13,D13:D635) -> 5.55 | L13: 77010000066 | M13: Внутри сети | N13: Внутри сети | P13: 77010000293 | R13: 77010000127
... A33: 77010000058 | B33: 1 | C33: Внутри сети | D33: 0.85 | E33: 2 | G33: 77010000092 | H33: Внутри сети | I33: =SUMIF(A33:A655,A33,D33:D655) -> 19.36 | L33: 77010000092 | M33: Внутри сети | N33: Внутри сети | P33: 77010000242 | R33: 77010000099
A34: 77010000064 | B34: 1 | C34: Внутри сети | D34: 0.85 | E34: 2 | G34: 77010000095 | H34: Внутри сети | I34: =SUMIF(A34:A656,A34,D34:D656) -> 2.55 | L34: 77010000095 | M34: Внутри сети | N34: Внутри сети | P34: 77010000249
A35: 77010000065 | B35: 1 | C35: Внутри сети | D35: 0.85 | E35: 2 | G35: 77010000009 | H35: Внутри сети | I35: =SUMIF(A35:A657,A35,D35:D657) -> 0.85 | L35: 77010000009 | M35: Внутри сети | N35: Внутри сети | P35: 77010000257
A36: 77010000037 | B36: 1 | C36: На городской | D36: 7.43 | E36: 2 | G36: 77010000010 | H36: Внутри сети | I36: =SUMIF(A36:A658,A36,D36:D658) -> 19.37 | L36: 77010000010 | M36: Внутри сети | N36: На городской | P36: 77010000289
A37: 77010000078 | B37: 1 | C37: Внутри сети | D37: 0.85 | E37: 2 | G37: 77010000016 | H37: Внутри сети | I37: =SUMIF(A37:A659,A37,D37:D659) -> 8.95 | L37: 77010000016 | M37: Внутри сети | N37: Внутри сети | P37: 77010000250
A38: 77010000086 | B38: 1 | C38: Внутри сети | D38: 0.85 | E38: 2 | G38: 77010000081 | H38: Внутри сети | I38: =SUMIF(A38:A660,A38,D38:D660) -> 0.85 | L38: 77010000081 | M38: Внутри сети | N38: Внутри сети | P38: 77010000292
A39: 77010000092 | B39: 1 | C39: Внутри сети | D39: 0.85 | E39: 2 | G39: 77010000067 | H39: Внутри сети | I39: =SUMIF(A39:A661,A39,D39:D661) -> 25.35 | L39: 77010000067 | M39: Внутри сети | N39: Внутри сети | P39: 77010000254
A40: 77010000095 | B40: 1 | C40: Внутри сети | D40: 0.85 | E40: 2 | G40: 77010000075 | H40: Внутри сети | I40: =SUMIF(A40:A662,A40,D40:D662) -> 0.85 | L40: 77010000075 | M40: Внутри сети | N40: Внутри сети | P40: 77010000260
A41: 77010000001 | B41: 1 | C41: Внутри сети | D41: 0.85 | E41: 2 | G41: 77010000088 | H41: Внутри сети | I41: =SUMIF(A41:A663,A41,D41:D663) -> 15.72 | L41: 77010000088 | M41: Внутри сети | N41: Внутри сети | P41: 77010000261
A42: 77010000009 | B42: 1 | C42: Внутри сети | D42: 0.85 | E42: 2 | G42: 77010000002 | H42: Внутри сети | I42: =SUMIF(A42:A664,A42,D42:D664) -> 4.69 | L42: 77010000002 | M42: Внутри сети | N42: Внутри сети | P42: 77010000282
A43: 77010000010 | B43: 1 | C43: Внутри сети | D43: 0.85 | E43: 2 | G43: 77010000049 | H43: Внутри сети | I43: =SUMIF(A43:A665,A43,D43:D665) -> 9.37 | L43: 77010000049 | M43: Внутри сети | N43: Внутри сети | P43: 77010000255
A44: 77010000016 | B44: 1 | C44: Внутри сети | D44: 0.85 | E44: 2 | G44: 77010000079 | H44: Внутри сети | I44: =SUMIF(A44:A666,A44,D44:D666) -> 6.82 | L44: 77010000079 | M44: Внутри сети | N44: Внутри сети | P44: 77010000307
A45: 77010000081 | B45: 1 | C45: Внутри сети | D45: 0.85 | E45: 2 | G45: 77010000048 | H45: Внутри сети | I45: =SUMIF(A45:A667,A45,D45:D667) -> 29.12 | L45: 77010000048 | M45: Внутри сети | N45: Внутри сети | P45: 77010000274
... A64: 77010000048 | B64: 1 | C64: Внутри сети | D64: 2.13 | E64: 5 | G64: 77010000069 | H64: Внутри сети | I64: =SUMIF(A64:A686,A64,D64:D686) -> 4.26 | L64: 77010000090 | M64: Внутри сети | N64: Внутри сети | P64: 77010000283
A65: 77010000067 | B65: 1 | C65: Внутри сети | D65: 2.13 | E65: 5 | G65: 77010000047 | H65: Внутри сети | I65: =SUMIF(A65:A687,A65,D65:D687) -> 26.63 | L65: 77010000076 | M65: Внутри сети | N65: Внутри сети
A66: 77010000089 | B66: 1 | C66: Внутри сети | D66: 2.13 | E66: 5 | G66: 77010000043 | H66: Внутри сети | I66: =SUMIF(A66:A688,A66,D66:D688) -> 2.13 | L66: 77010000035 | M66: Внутри сети | N66: Внутри сети
A67: 77010000093 | B67: 1 | C67: Внутри сети | D67: 2.13 | E67: 5 | G67: 77010000013 | H67: Внутри сети | I67: =SUMIF(A67:A689,A67,D67:D689) -> 4.69 | L67: 77010000023 | M67: Внутри сети | N67: Внутри сети
A68: 77010000018 | B68: 1 | C68: Внутри сети | D68: 2.13 | E68: 5 | G68: 77010000036 | H68: Внутри сети | I68: =SUMIF(A68:A690,A68,D68:D690) -> 6.82 | L68: 77010000039 | M68: Внутри сети | N68: Внутри сети
A69: 77010000048 | B69: 1 | C69: Внутри сети | D69: 2.13 | E69: 5 | G69: 77010000074 | H69: Внутри сети | I69: =SUMIF(A69:A691,A69,D69:D691) -> 2.13 | L69: 77010000058 | M69: На городской | N69: Внутри сети
A70: 77010000073 | B70: 1 | C70: На городской | D70: 7.43 | E70: 5 | G70: 77010000059 | H70: Внутри сети | I70: =SUMIF(A70:A692,A70,D70:D692) -> 10.41 | L70: 77010000069 | M70: Внутри сети | N70: На городской
A71: 77010000056 | B71: 1 | C71: На других операторов | D71: 7.43 | E71: 6 | G71: 77010000077 | H71: Внутри сети | I71: =SUMIF(A71:A693,A71,D71:D693) -> 22.77 | L71: 77010000067 | M71: На межнар | N71: На других операторов
A72: 77010000057 | B72: 1 | C72: Внутри сети | D72: 2.56 | E72: 6 | G72: 77010000083 | H72: Внутри сети | I72: =SUMIF(A72:A694,A72,D72:D694) -> 15.77 | L72: 77010000047 | M72: Внутри сети | N72: Внутри сети
A73: 77010000046 | B73: 1 | C73: Внутри сети | D73: 2.56 | E73: 6 | G73: 77010000011 | H73: Внутри сети | I73: =SUMIF(A73:A695,A73,D73:D695) -> 6.82 | L73: 77010000017 | M73: На межнар | N73: Внутри сети
A74: 77010000053 | B74: 1 | C74: На межнар | D74: 24.5 | E74: 6 | G74: 77010000027 | H74: На других операторов | I74: =SUMIF(A74:A696,A74,D74:D696) -> 41.55 | L74: 77010000043 | M74: Внутри сети | N74: На межнар
A75: 77010000093 | B75: 1 | C75: Внутри сети | D75: 2.56 | E75: 6 | G75: 77010000032 | H75: Внутри сети | I75: =SUMIF(A75:A697,A75,D75:D697) -> 2.56 | L75: 77010000013 | M75: Внутри сети | N75: Внутри сети
A76: 77010000085 | B76: 1 | C76: Внутри сети | D76: 0.83 | E76: 6 | G76: 77010000022 | H76: Внутри сети | I76: =SUMIF(A76:A698,A76,D76:D698) -> 0.83 | L76: 77010000036 | M76: Внутри сети | N76: Внутри сети
... A293: 77010000116 | B293: 2 | C293: Внутри сети | D293: 10.23 | E293: 24 | G293: 77010000283 | H293: Внутри сети | I293: =SUMIF(A293:A915,A293,D293:D915) -> 10.23 | L293: 77010000281 | M293: Внутри сети | N293: Внутри сети
...

Sheet Sheet2
A1: =VLOOKUP(77010000055,'База данных'!A:B,2,FALSE) -> 1
A2: =SUMIF('База данных'!B:B,"1",'База данных'!E:E) -> 2705
A3: {=INDEX('База данных'!A:A,MATCH(MAX(_xlfn._xlws.FILTER(SUMIF('База данных'!A:A,'База данных'!A:A,'База данных'!E:E),'База данных'!B:B="5")),SUMIF('База данных'!A:A,'База данных'!A:A,'База данных'!E:E),0))} -> #NAME?
